Workbook

Sheet 🏠 ÍNDICE
B2: INDICE DE NACEGACIÓN
B4: 📂 DATOS
B5: Hojas de introducción de datos
C6: ➜ 📊 Datos Crudos 1
C7: ➜ 📋 Datos Crudos 2
B9: 📈 VISUAL SEGUIMIENTOS
B10: Dashboards de seguimiento
C11: ➜ 📅 Seg. Semanal
C12: ➜ 📆 Seg. Mensual
B14: 🔍 SEGUIMIENTO DE SECCIÓN SEMANAL
B15: Dashboards de alertas — ver y actuar
C16: ➜ 🚨 Visual Sección

Sheet DATOS CRUDOS PLANTILLA
B2: DATOS CRUDOS — OT: SEGUIMIENTOS MENSUAL Y SEMANAL — 2026
B4: ▌ BLOQUE A — SEGUIMIENTO SEMANAL
B5: SECCIÓN | C5: SEM 1 | F5: SEM 2 | I5: SEM 3 | L5: SEM 4 | O5: SEM 5
C6: KPI | D6: KPI | E6: KPI | F6: KPI | G6: KPI | H6: KPI | I6: KPI | J6: KPI | K6: KPI | L6: KPI | M6: KPI | N6: KPI | O6: KPI | P6: KPI | Q6: KPI
B7: Producto 1
B8: Producto 2
B9: Producto 3
B10: Producto 4
B11: Producto 5
B12: Producto 6
B13: Producto 7
B14: Producto 8
B15: Producto 9
B16: TIENDA
B18: ▌ BLOQUE B — SEGUIMIENTO MENSUAL
B19: MÉTRICA | C19: ENE | D19: FEB | E19: MAR | F19: ABR | G19: MAY | H19: JUN | I19: JUL | J19: AGO | K19: SEP | L19: OCT | M19: NOV | N19: DIC | O19: TOTAL AÑO
B20: KPI | O20: =SUM(C20:N20) -> 0
B21: KPI | O21: =SUM(C21:N21) -> 0
B22: KPI | O22: =SUM(C22:N22) -> 0
B23: KPI | O23: =SUM(C23:N23) -> 0
B24: KPI | O24: =SUM(C24:N24) -> 0
B25: KPI | O25: =SUM(C25:N25) -> 0
B26: KPI | O26: =SUM(C26:N26) -> 0
B27: KPI | O27: =SUM(C27:N27) -> 0
B28: KPI | O28: =SUM(C28:N28) -> 0
B29: KPI | O29: =SUM(C29:N29) -> 0
B30: KPI | O30: =SUM(C30:N30) -> 0
B31: KPI | O31: =SUM(C31:N31) -> 0
B32: KPI | O32: =SUM(C32:N32) -> 0
B33: ⚠️ INSTRUCCIONES:
B35: BLOQUE C
B36: SEMANA 1 | E36: SEMANA 2 | H36: SEMANA 3 | K36: SEMANA 4 | N36: SEMANA 5
B37: PRODUCTO | C37: KPI | D37: KPI | E37: PRODUCTO | F37: KPI | G37: KPI | H37: PRODUCTO | I37: KPI | J37: KPI | K37: PRODUCTO | L37: KPI | M37: KPI | N37: PRODUCTO | O37: KPI | P37: KPI

Sheet DATOS SECCION PLANTILLA
C2: DATOS CRUDOS
C4: ▌ BLOQUE 1 — ALERTAS SEMANALES
C5: ENERO | J5: FEBRERO | Q5: MARZO | X5: ABRIL | AE5: MAYO | AL5: JUNIO | AS5: JULIO | AZ5: AGOSTO | BG5: SEPTIEMBRE | BN5: OCTUBRE | BU5: NOVIEMBRE | CB5: DICIEMBRE
C6: SEMANA | D6: FAMILIA | E6: KPI | F6: KPI | G6: KPI | H6: KPI | J6: SEMANA | K6: FAMILIA | L6: KPI | M6: KPI | N6: KPI | O6: KPI | Q6: SEMANA | R6: FAMILIA | S6: KPI | T6: KPI | U6: KPI | V6: KPI | X6: SEMANA | Y6: FAMILIA | Z6: KPI | AA6: KPI | AB6: KPI | AC6: KPI | AE6: SEMANA | AF6: FAMILIA | AG6: KPI | AH6: KPI | AI6: KPI | AJ6: KPI | AL6: SEMANA | AM6: FAMILIA | AN6: KPI | AO6: KPI | AP6: KPI | AQ6: KPI | AS6: SEMANA | AT6: FAMILIA | AU6: KPI | AV6: KPI | AW6: KPI | AX6: KPI | AZ6: SEMANA | BA6: FAMILIA | BB6: KPI | BC6: KPI | BD6: KPI | BE6: KPI | BG6: SEMANA | BH6: FAMILIA | BI6: KPI | BJ6: KPI | BK6: KPI | BL6: KPI | BN6: SEMANA | BO6: FAMILIA | BP6: KPI | BQ6: KPI | BR6: KPI | BS6: KPI | BU6: SEMANA | BV6: FAMILIA | BW6: KPI | BX6: KPI | BY6: KPI | BZ6: KPI | CB6: SEMANA | CC6: FAMILIA | CD6: KPI | CE6: KPI | CF6: KPI | CG6: KPI
C7: Semana 1 | D7: FAM A | J7: Semana 6 | K7: FAM A | Q7: Semana 10 | R7: FAM A | X7: Semana 14 | Y7: FAM A | AE7: Semana 19 | AF7: FAM A | AL7: Semana 23 | AM7: FAM A | AS7: Semana 27 | AT7: FAM A | AZ7: Semana 32 | BA7: FAM A | BG7: Semana 36 | BH7: FAM A | BN7: Semana 40 | BO7: FAM A | BU7: Semana 44 | BV7: FAM A | CB7: Semana 48 | CC7: FAM A
D8: FAM B | K8: FAM B | R8: FAM B | Y8: FAM B | AF8: FAM B | AM8: FAM B | AT8: FAM B | BA8: FAM B | BH8: FAM B | BO8: FAM B | BV8: FAM B | CC8: FAM B
D9: FAM C | K9: FAM C | R9: FAM C | Y9: FAM C | AF9: FAM C | AM9: FAM C | AT9: FAM C | BA9: FAM C | BH9: FAM C | BO9: FAM C | BV9: FAM C | CC9: FAM C
C11: Semana 2 | D11: FAM A | J11: Semana 7 | K11: FAM A | Q11: Semana 11 | R11: FAM A | X11: Semana 15 | Y11: FAM A | AE11: Semana 20 | AF11: FAM A | AL11: Semana 24 | AM11: FAM A | AS11: Semana 28 | AT11: FAM A | AZ11: Semana 33 | BA11: FAM A | BG11: Semana 37 | BH11: FAM A | BN11: Semana 41 | BO11: FAM A | BU11: Semana 45 | BV11: FAM A | CB11: Semana 49 | CC11: FAM A
D12: FAM B | K12: FAM B | R12: FAM B | Y12: FAM B | AF12: FAM B | AM12: FAM B | AT12: FAM B | BA12: FAM B | BH12: FAM B | BO12: FAM B | BV12: FAM B | CC12: FAM B
D13: FAM C | K13: FAM C | R13: FAM C | Y13: FAM C | AF13: FAM C | AM13: FAM C | AT13: FAM C | BA13: FAM C | BH13: FAM C | BO13: FAM C | BV13: FAM C | CC13: FAM C
C15: Semana 3 | D15: FAM A | J15: Semana 8 | K15: FAM A | Q15: Semana 12 | R15: FAM A | X15: Semana 16 | Y15: FAM A | AE15: Semana 21 | AF15: FAM A | AL15: Semana 25 | AM15: FAM A | AS15: Semana 29 | AT15: FAM A | AZ15: Semana 34 | BA15: FAM A | BG15: Semana 38 | BH15: FAM A | BN15: Semana 42 | BO15: FAM A | BU15: Semana 46 | BV15: FAM A | CB15: Semana 50 | CC15: FAM A
D16: FAM B | K16: FAM B | R16: FAM B | Y16: FAM B | AF16: FAM B | AM16: FAM B | AT16: FAM B | BA16: FAM B | BH16: FAM B | BO16: FAM B | BV16: FAM B | CC16: FAM B
D17: FAM C | K17: FAM C | R17: FAM C | Y17: FAM C | AF17: FAM C | AM17: FAM C | AT17: FAM C | BA17: FAM C | BH17: FAM C | BO17: FAM C | BV17: FAM C | CC17: FAM C
C19: Semana 4 | D19: FAM A | J19: Semana 9 | K19: FAM A | Q19: Semana 13 | R19: FAM A | X19: Semana 17 | Y19: FAM A | AE19: Semana 22 | AF19: FAM A | AL19: Semana 26 | AM19: FAM A | AS19: Semana 30 | AT19: FAM A | AZ19: Semana 35 | BA19: FAM A | BG19: Semana 39 | BH19: FAM A | BN19: Semana 43 | BO19: FAM A | BU19: Semana 47 | BV19: FAM A | CB19: Semana 51 | CC19: FAM A
D20: FAM B | K20: FAM B | R20: FAM B | Y20: FAM B | AF20: FAM B | AM20: FAM B | AT20: FAM B | BA20: FAM B | BH20: FAM B | BO20: FAM B | BV20: FAM B | CC20: FAM B
D21: FAM C | K21: FAM C | R21: FAM C | Y21: FAM C | AF21: FAM C | AM21: FAM C | AT21: FAM C | BA21: FAM C | BH21: FAM C | BO21: FAM C | BV21: FAM C | CC21: FAM C
C23: Semana 5 | D23: FAM A | X23: Semana 18 | Y23: FAM A | AS23: Semana 31 | AT23: FAM A
D24: FAM B | Y24: FAM B | AT24: FAM B
D25: FAM C | Y25: FAM C | AT25: FAM C
C27: ▌ BLOQUE 2 — SEGUIMIENTO MENSUAL
C28: MÉTRICA | D28: ENE | E28: FEB | F28: MAR | G28: ABR | H28: MAY | I28: JUN | J28: JUL | K28: AGO | L28: SEP | M28: OCT | N28: NOV | O28: DIC | P28: TOTAL AÑO
B29: 2025 | C29: KPI | P29: =SUM(D29:O29) -> 0
C30: KPI | P30: =SUM(D30:O30) -> 0
C31: KPI | P31: =SUM(D31:O31) -> 0
C32: KPI | P32: =SUM(D32:O32) -> 0
C33: KPI | P33: =SUM(D33:O33) -> 0
C34: KPI | P34: =SUM(D34:O34) -> 0
B36: 2026 | C36: KPI | P36: =SUM(D36:O36) -> 0
C37: KPI | P37: =SUM(D37:O37) -> 0
C38: KPI | P38: =SUM(D38:O38) -> 0
C39: KPI | P39: =SUM(D39:O39) -> 0
C40: KPI | P40: =SUM(D40:O40) -> 0
C41: KPI | P41: =SUM(D41:O41) -> 0
C43: ⚠️ Instrucciones

Sheet VISUAL SEG MENSUAL PLANTILLA
B2: 📦 DEMARCA — SEGUIMIENTO MENSUAL | N2: REFERENCIAS KPI
B4: GAP | G4: KPIs | N4: PILOTAJE ANUAL TOTAL | P4: -129071
B5: MES | C5: GAP (€) | D5: PILOTAJE (€) | E5: ESTADO | G5: MES | H5: KPI | I5: VALOR | J5: ESTADO
B7: ENERO | C7: ='DATOS CRUDOS PLANTILLA'!C24 | D7: ='DATOS CRUDOS PLANTILLA'!C22 | E7: =IF(C7="","⏳ PENDIENTE", IF(C7>0, "🔴 NEGATIVO","✅ POSITIVO")) -> ⏳ PENDIENTE | G7: ENERO | H7: KPI | I7: ='DATOS CRUDOS PLANTILLA'!C27 | J7: =IF(I7="","⏳ PENDIENTE", IF(I7>9,"✅ OK","🔴 Obj: >9")) -> ⏳ PENDIENTE | M7: Grafico
B8: FEBRERO | C8: ='DATOS CRUDOS PLANTILLA'!D24 | D8: ='DATOS CRUDOS PLANTILLA'!D22 | E8: =IF(C8="","⏳ PENDIENTE", IF(C8>0, "🔴 NEGATIVO","✅ POSITIVO")) -> ⏳ PENDIENTE | H8: KPI | I8: ='DATOS CRUDOS PLANTILLA'!C28 | J8: =IF(I8="","⏳ PENDIENTE", IF(I8>95,"✅ OK","🔴 Obj: >95")) -> ⏳ PENDIENTE
B9: MARZO | C9: ='DATOS CRUDOS PLANTILLA'!E24 | D9: ='DATOS CRUDOS PLANTILLA'!E22 | E9: =IF(C9="","⏳ PENDIENTE", IF(C9>0, "🔴 NEGATIVO","✅ POSITIVO")) -> ⏳ PENDIENTE | H9: KPI | I9: ='DATOS CRUDOS PLANTILLA'!C29 | J9: =IF(I9="","⏳ PENDIENTE", IF(I9<2,"✅ OK","🔴 Obj: <2")) -> ⏳ PENDIENTE
B10: ABRIL | C10: ='DATOS CRUDOS PLANTILLA'!F24 | D10: ='DATOS CRUDOS PLANTILLA'!F22 | E10: =IF(C10="","⏳ PENDIENTE", IF(C10>0, "🔴 NEGATIVO","✅ POSITIVO")) -> ⏳ PENDIENTE | H10: KPI | I10: ='DATOS CRUDOS PLANTILLA'!C30 | J10: Producto 1
B11: MAYO | C11: ='DATOS CRUDOS PLANTILLA'!G24 | D11: ='DATOS CRUDOS PLANTILLA'!G22 | E11: =IF(C11="","⏳ PENDIENTE", IF(C11>0, "🔴 NEGATIVO","✅ POSITIVO")) -> ⏳ PENDIENTE | H11: KPI | I11: ='DATOS CRUDOS PLANTILLA'!C31 | J11: =IF(I11="","⏳ PENDIENTE", IF(I11>2000,"✅ OK","🔴 Obj: 2000")) -> ⏳ PENDIENTE
B12: JUNIO | C12: ='DATOS CRUDOS PLANTILLA'!H24 | D12: ='DATOS CRUDOS PLANTILLA'!H22 | E12: =IF(C12="","⏳ PENDIENTE", IF(C12>0, "🔴 NEGATIVO","✅ POSITIVO")) -> ⏳ PENDIENTE | G12: FEBRERO | H12: KPI | I12: ='DATOS CRUDOS PLANTILLA'!D27 | J12: =IF(I12="","⏳ PENDIENTE", IF(I12>9,"✅ OK","🔴 Obj: >9")) -> ⏳ PENDIENTE
B13: JULIO | C13: ='DATOS CRUDOS PLANTILLA'!I24 | D13: ='DATOS CRUDOS PLANTILLA'!I22 | E13: =IF(C13="","⏳ PENDIENTE", IF(C13>0, "🔴 NEGATIVO","✅ POSITIVO")) -> ⏳ PENDIENTE | H13: KPI | I13: ='DATOS CRUDOS PLANTILLA'!D28 | J13: =IF(I13="","⏳ PENDIENTE", IF(I13>95,"✅ OK","🔴 Obj: >95")) -> ⏳ PENDIENTE
B14: AGOSTO | C14: ='DATOS CRUDOS PLANTILLA'!J24 | D14: ='DATOS CRUDOS PLANTILLA'!J22 | E14: =IF(C14="","⏳ PENDIENTE", IF(C14>0, "🔴 NEGATIVO","✅ POSITIVO")) -> ⏳ PENDIENTE | H14: KPI | I14: ='DATOS CRUDOS PLANTILLA'!D29 | J14: =IF(I14="","⏳ PENDIENTE", IF(I14<2,"✅ OK","🔴 Obj: <2")) -> ⏳ PENDIENTE
B15: SEPTIEMBRE | C15: ='DATOS CRUDOS PLANTILLA'!K24 | D15: ='DATOS CRUDOS PLANTILLA'!K22 | E15: =IF(C15="","⏳ PENDIENTE", IF(C15>0, "🔴 NEGATIVO","✅ POSITIVO")) -> ⏳ PENDIENTE | H15: KPI | I15: ='DATOS CRUDOS PLANTILLA'!D30 | J15: Sección A
B16: OCTUBRE | C16: ='DATOS CRUDOS PLANTILLA'!L24 | D16: ='DATOS CRUDOS PLANTILLA'!L22 | E16: =IF(C16="","⏳ PENDIENTE", IF(C16>0, "🔴 NEGATIVO","✅ POSITIVO")) -> ⏳ PENDIENTE | H16: KPI | I16: ='DATOS CRUDOS PLANTILLA'!D31 | J16: =IF(I16="","⏳ PENDIENTE", IF(I16>2000,"✅ OK","🔴 Obj: 2000")) -> ⏳ PENDIENTE
B17: NOVIEMBRE | C17: ='DATOS CRUDOS PLANTILLA'!M24 | D17: ='DATOS CRUDOS PLANTILLA'!M22 | E17: =IF(C17="","⏳ PENDIENTE", IF(C17>0, "🔴 NEGATIVO","✅ POSITIVO")) -> ⏳ PENDIENTE | G17: MARZO | H17: KPI | I17: ='DATOS CRUDOS PLANTILLA'!E27 | J17: =IF(I17="","⏳ PENDIENTE", IF(I17>9,"✅ OK","🔴 Obj: >9")) -> ⏳ PENDIENTE
B18: DICIEMBRE | C18: ='DATOS CRUDOS PLANTILLA'!N24 | D18: ='DATOS CRUDOS PLANTILLA'!N22 | E18: =IF(C18="","⏳ PENDIENTE", IF(C18>0, "🔴 NEGATIVO","✅ POSITIVO")) -> ⏳ PENDIENTE | H18: KPI | I18: ='DATOS CRUDOS PLANTILLA'!E28 | J18: =IF(I18="","⏳ PENDIENTE", IF(I18>95,"✅ OK","🔴 Obj: >95")) -> ⏳ PENDIENTE
B19: TOTAL | H19: KPI | I19: ='DATOS CRUDOS PLANTILLA'!E29 | J19: =IF(I19="","⏳ PENDIENTE", IF(I19<2,"✅ OK","🔴 Obj: <2")) -> ⏳ PENDIENTE
H20: KPI | I20: ='DATOS CRUDOS PLANTILLA'!E30 | J20: ℹ️ Sin objetivo
H21: KPI | I21: ='DATOS CRUDOS PLANTILLA'!E31 | J21: =IF(I21="","⏳ PENDIENTE", IF(I21>2000,"✅ OK","🔴 Obj: 2000")) -> ⏳ PENDIENTE
G22: ABRIL | H22: KPI | I22: ='DATOS CRUDOS PLANTILLA'!F27 | J22: =IF(I22="","⏳ PENDIENTE", IF(I22>9,"✅ OK","🔴 Obj: >9")) -> ⏳ PENDIENTE
H23: KPI | I23: ='DATOS CRUDOS PLANTILLA'!F28 | J23: =IF(I23="","⏳ PENDIENTE", IF(I23>95,"✅ OK","🔴 Obj: >95")) -> ⏳ PENDIENTE
H24: KPI | I24: ='DATOS CRUDOS PLANTILLA'!F29 | J24: =IF(I24="","⏳ PENDIENTE", IF(I24<2,"✅ OK","🔴 Obj: <2")) -> ⏳ PENDIENTE
H25: KPI | I25: ='DATOS CRUDOS PLANTILLA'!F30 | J25: ℹ️ Sin objetivo
H26: KPI | I26: ='DATOS CRUDOS PLANTILLA'!F31 | J26: =IF(I26="","⏳ PENDIENTE", IF(I26>2000,"✅ OK","🔴 Obj: 2000")) -> ⏳ PENDIENTE
G27: MAYO | H27: KPI | I27: ='DATOS CRUDOS PLANTILLA'!G27 | J27: =IF(I27="","⏳ PENDIENTE", IF(I27>9,"✅ OK","🔴 Obj: >9")) -> ⏳ PENDIENTE
H28: KPI | I28: ='DATOS CRUDOS PLANTILLA'!G28 | J28: =IF(I28="","⏳ PENDIENTE", IF(I28>95,"✅ OK","🔴 Obj: >95")) -> ⏳ PENDIENTE
H29: KPI | I29: ='DATOS CRUDOS PLANTILLA'!G29 | J29: =IF(I29="","⏳ PENDIENTE", IF(I29<2,"✅ OK","🔴 Obj: <2")) -> ⏳ PENDIENTE
H30: KPI | I30: ='DATOS CRUDOS PLANTILLA'!G30 | J30: Región Sur
H31: KPI | I31: ='DATOS CRUDOS PLANTILLA'!G31 | J31: =IF(I31="","⏳ PENDIENTE", IF(I31>2000,"✅ OK","🔴 Obj: 2000")) -> ⏳ PENDIENTE
G32: JUNIO | H32: KPI | I32: ='DATOS CRUDOS PLANTILLA'!H27 | J32: =IF(I32="","⏳ PENDIENTE", IF(I32>9,"✅ OK","🔴 Obj: >9")) -> ⏳ PENDIENTE
H33: KPI | I33: ='DATOS CRUDOS PLANTILLA'!H28 | J33: =IF(I33="","⏳ PENDIENTE", IF(I33>95,"✅ OK","🔴 Obj: >95")) -> ⏳ PENDIENTE
H34: KPI | I34: ='DATOS CRUDOS PLANTILLA'!H29 | J34: =IF(I34="","⏳ PENDIENTE", IF(I34<2,"✅ OK","🔴 Obj: <2")) -> ⏳ PENDIENTE
H35: KPI | I35: ='DATOS CRUDOS PLANTILLA'!H30 | J35: ℹ️ Sin objetivo
H36: KPI | I36: ='DATOS CRUDOS PLANTILLA'!H31 | J36: =IF(I36="","⏳ PENDIENTE", IF(I36>2000,"✅ OK","🔴 Obj: 2000")) -> ⏳ PENDIENTE
G37: JULIO | H37: KPI | I37: ='DATOS CRUDOS PLANTILLA'!I27 | J37: =IF(I37="","⏳ PENDIENTE", IF(I37>9,"✅ OK","🔴 Obj: >9")) -> ⏳ PENDIENTE
H38: KPI | I38: ='DATOS CRUDOS PLANTILLA'!I28 | J38: =IF(I38="","⏳ PENDIENTE", IF(I38>95,"✅ OK","🔴 Obj: >95")) -> ⏳ PENDIENTE
H39: KPI | I39: ='DATOS CRUDOS PLANTILLA'!I29 | J39: =IF(I39="","⏳ PENDIENTE", IF(I39<2,"✅ OK","🔴 Obj: <2")) -> ⏳ PENDIENTE
H40: KPI | I40: ='DATOS CRUDOS PLANTILLA'!I30 | J40: ℹ️ Sin objetivo
H41: KPI | I41: ='DATOS CRUDOS PLANTILLA'!I31 | J41: =IF(I41="","⏳ PENDIENTE", IF(I41>2000,"✅ OK","🔴 Obj: 2000")) -> ⏳ PENDIENTE
G42: AGOSTO | H42: KPI | I42: ='DATOS CRUDOS PLANTILLA'!J27 | J42: =IF(I42="","⏳ PENDIENTE", IF(I42>9,"✅ OK","🔴 Obj: >9")) -> ⏳ PENDIENTE
H43: KPI | I43: ='DATOS CRUDOS PLANTILLA'!J28 | J43: =IF(I43="","⏳ PENDIENTE", IF(I43>95,"✅ OK","🔴 Obj: >95")) -> ⏳ PENDIENTE
...

Sheet VISUAL SEG. SEMANAL PLANTILLA
B2: 📊 SEGUIMIENTO SEMANAL — 2026
B4: SEMANA 1 | G4: SEMANA 2
B5: SECCIÓN | C5: KPI | D5: KPI | E5: KPI | G5: SECCIÓN | H5: KPI | I5: KPI | J5: KPI
B6: Producto 1 | C6: ='DATOS CRUDOS PLANTILLA'!C7 | D6: ='DATOS CRUDOS PLANTILLA'!D7 | E6: ='DATOS CRUDOS PLANTILLA'!E7 | G6: Producto 1 | H6: ='DATOS CRUDOS PLANTILLA'!F7 | I6: ='DATOS CRUDOS PLANTILLA'!G7 | J6: ='DATOS CRUDOS PLANTILLA'!H7
B7: Producto 2 | C7: ='DATOS CRUDOS PLANTILLA'!C8 | D7: ='DATOS CRUDOS PLANTILLA'!D8 | E7: ='DATOS CRUDOS PLANTILLA'!E8 | G7: Producto 2 | H7: ='DATOS CRUDOS PLANTILLA'!F8 | I7: ='DATOS CRUDOS PLANTILLA'!G8 | J7: ='DATOS CRUDOS PLANTILLA'!H8
B8: Producto 3 | C8: ='DATOS CRUDOS PLANTILLA'!C9 | D8: ='DATOS CRUDOS PLANTILLA'!D9 | E8: ='DATOS CRUDOS PLANTILLA'!E9 | G8: Producto 3 | H8: ='DATOS CRUDOS PLANTILLA'!F9 | I8: ='DATOS CRUDOS PLANTILLA'!G9 | J8: ='DATOS CRUDOS PLANTILLA'!H9
B9: Producto 4 | C9: ='DATOS CRUDOS PLANTILLA'!C10 | D9: ='DATOS CRUDOS PLANTILLA'!D10 | E9: ='DATOS CRUDOS PLANTILLA'!E10 | G9: Producto 4 | H9: ='DATOS CRUDOS PLANTILLA'!F10 | I9: ='DATOS CRUDOS PLANTILLA'!G10 | J9: ='DATOS CRUDOS PLANTILLA'!H10
B10: Producto 5 | C10: ='DATOS CRUDOS PLANTILLA'!C11 | D10: ='DATOS CRUDOS PLANTILLA'!D11 | E10: ='DATOS CRUDOS PLANTILLA'!E11 | G10: Producto 5 | H10: ='DATOS CRUDOS PLANTILLA'!F11 | I10: ='DATOS CRUDOS PLANTILLA'!G11 | J10: ='DATOS CRUDOS PLANTILLA'!H11
B11: Producto 6 | C11: ='DATOS CRUDOS PLANTILLA'!C12 | D11: ='DATOS CRUDOS PLANTILLA'!D12 | E11: ='DATOS CRUDOS PLANTILLA'!E12 | G11: Producto 6 | H11: ='DATOS CRUDOS PLANTILLA'!F12 | I11: ='DATOS CRUDOS PLANTILLA'!G12 | J11: ='DATOS CRUDOS PLANTILLA'!H12
B12: Producto 7 | C12: ='DATOS CRUDOS PLANTILLA'!C13 | D12: ='DATOS CRUDOS PLANTILLA'!D13 | E12: ='DATOS CRUDOS PLANTILLA'!E13 | G12: Producto 7 | H12: ='DATOS CRUDOS PLANTILLA'!F13 | I12: ='DATOS CRUDOS PLANTILLA'!G13 | J12: ='DATOS CRUDOS PLANTILLA'!H13
B13: Producto 8 | C13: ='DATOS CRUDOS PLANTILLA'!C14 | D13: ='DATOS CRUDOS PLANTILLA'!D14 | E13: ='DATOS CRUDOS PLANTILLA'!E14 | G13: Producto 8 | H13: ='DATOS CRUDOS PLANTILLA'!F14 | I13: ='DATOS CRUDOS PLANTILLA'!G14 | J13: ='DATOS CRUDOS PLANTILLA'!H14
B14: Producto 9 | C14: ='DATOS CRUDOS PLANTILLA'!C15 | D14: ='DATOS CRUDOS PLANTILLA'!D15 | E14: ='DATOS CRUDOS PLANTILLA'!E15 | G14: Producto 9 | H14: ='DATOS CRUDOS PLANTILLA'!F15 | I14: ='DATOS CRUDOS PLANTILLA'!G15 | J14: ='DATOS CRUDOS PLANTILLA'!H15
B15: TOTAL | C15: ='DATOS CRUDOS PLANTILLA'!C16 | D15: ='DATOS CRUDOS PLANTILLA'!D16 | E15: ='DATOS CRUDOS PLANTILLA'!E16 | G15: TOTAL | H15: ='DATOS CRUDOS PLANTILLA'!F16 | I15: ='DATOS CRUDOS PLANTILLA'!G16 | J15: ='DATOS CRUDOS PLANTILLA'!H16
B19: Semana 1 | G19: Semana 2
B20: Producto | C20: KPI | D20: KPI | E20: Accion | G20: Producto | H20: KPI | I20: KPI | J20: Accion
B21: ='DATOS CRUDOS PLANTILLA'!B38 | C21: ='DATOS CRUDOS PLANTILLA'!C38 | D21: ='DATOS CRUDOS PLANTILLA'!D38 | G21: ='DATOS CRUDOS PLANTILLA'!E38 | H21: ='DATOS CRUDOS PLANTILLA'!F38 | I21: ='DATOS CRUDOS PLANTILLA'!G38
B22: ='DATOS CRUDOS PLANTILLA'!B39 | C22: ='DATOS CRUDOS PLANTILLA'!C39 | D22: ='DATOS CRUDOS PLANTILLA'!D39 | G22: ='DATOS CRUDOS PLANTILLA'!E39 | H22: ='DATOS CRUDOS PLANTILLA'!F39 | I22: ='DATOS CRUDOS PLANTILLA'!G39
B23: ='DATOS CRUDOS PLANTILLA'!B40 | C23: ='DATOS CRUDOS PLANTILLA'!C40 | D23: ='DATOS CRUDOS PLANTILLA'!D40 | G23: ='DATOS CRUDOS PLANTILLA'!E40 | H23: ='DATOS CRUDOS PLANTILLA'!F40 | I23: ='DATOS CRUDOS PLANTILLA'!G40
B24: ='DATOS CRUDOS PLANTILLA'!B41 | C24: ='DATOS CRUDOS PLANTILLA'!C41 | D24: ='DATOS CRUDOS PLANTILLA'!D41 | G24: ='DATOS CRUDOS PLANTILLA'!E41 | H24: ='DATOS CRUDOS PLANTILLA'!F41 | I24: ='DATOS CRUDOS PLANTILLA'!G41
B25: ='DATOS CRUDOS PLANTILLA'!B42 | C25: ='DATOS CRUDOS PLANTILLA'!C42 | D25: ='DATOS CRUDOS PLANTILLA'!D42 | G25: ='DATOS CRUDOS PLANTILLA'!E42 | H25: ='DATOS CRUDOS PLANTILLA'!F42 | I25: ='DATOS CRUDOS PLANTILLA'!G42
B26: ='DATOS CRUDOS PLANTILLA'!B43 | C26: ='DATOS CRUDOS PLANTILLA'!C43 | D26: ='DATOS CRUDOS PLANTILLA'!D43 | G26: ='DATOS CRUDOS PLANTILLA'!E43 | H26: ='DATOS CRUDOS PLANTILLA'!F43 | I26: ='DATOS CRUDOS PLANTILLA'!G43

Sheet VISUAL SEMANAL SECCION PLANTILL
B2: 🚨 PRODUCTOS EN ALERTA — SECCIÓN X
B4: 🔴 Demarca negativa = pérdida 🟢 Demarca positiva ✍️ Rellena tu plan de acción
B6: ENERO
B7: SEMANA 1
B8: FAMILIA | C8: KPI | D8: PRODUCTO | G8: ✍️ PLAN DE ACCIÓN
B9: Producto 1 | C9: ='DATOS SECCION PLANTILLA'!E7 | D9: ='DATOS SECCION PLANTILLA'!F7
D10: ='DATOS SECCION PLANTILLA'!G7
D11: ='DATOS SECCION PLANTILLA'!H7
B12: Producto 2 | C12: ='DATOS SECCION PLANTILLA'!E8 | D12: ='DATOS SECCION PLANTILLA'!F8
D13: ='DATOS SECCION PLANTILLA'!G8
D14: ='DATOS SECCION PLANTILLA'!H8
B15: Producto 3 | C15: ='DATOS SECCION PLANTILLA'!E9 | D15: ='DATOS SECCION PLANTILLA'!F9
D16: ='DATOS SECCION PLANTILLA'!G9
D17: ='DATOS SECCION PLANTILLA'!H9

Sheet DATOS CRUDOS EJEMPLO
B2: DATOS CRUDOS — OT: SEGUIMIENTOS MENSUAL Y SEMANAL — 2026
B4: ▌ BLOQUE A — SEGUIMIENTO SEMANAL
B5: SECCIÓN | C5: SEM 1 | F5: SEM 2 | I5: SEM 3 | L5: SEM 4 | O5: SEM 5 | R5: SEM 6 | U5: SEM 7 | X5: SEM 8 | AA5: SEM 9 | AD5: SEM 10 | AG5: SEM 11 | AJ5: SEM 12 | AM5: SEM 13 | AP5: SEM 14 | AS5: SEM 15 | AV5: SEM 16 | AY5: SEM 17 | BB5: SEM 18 | BE5: SEM 19 | BH5: SEM 20 | BK5: SEM 21
C6: KPI | D6: KPI | E6: KPI | F6: KPI | G6: KPI | H6: KPI | I6: KPI | J6: KPI | K6: KPI | L6: KPI | M6: KPI | N6: KPI | O6: KPI | P6: KPI | Q6: KPI | R6: KPI | S6: KPI | T6: KPI | U6: KPI | V6: KPI | W6: KPI | X6: KPI | Y6: KPI | Z6: KPI | AA6: KPI | AB6: KPI | AC6: KPI | AD6: KPI | AE6: KPI | AF6: KPI | AG6: KPI | AH6: KPI | AI6: KPI | AJ6: KPI | AK6: KPI | AL6: KPI | AM6: KPI | AN6: KPI | AO6: KPI | AP6: KPI | AQ6: KPI | AR6: KPI | AS6: KPI | AT6: KPI | AU6: KPI | AV6: KPI | AW6: KPI | AX6: KPI | AY6: KPI | AZ6: KPI | BA6: KPI | BB6: KPI | BC6: KPI | BD6: KPI | BE6: KPI | BF6: KPI | BG6: KPI | BH6: KPI | BI6: KPI | BJ6: KPI | BK6: KPI | BL6: KPI | BM6: KPI
B7: Producto 1 | C7: =RANDBETWEEN(0,100) -> 93 | D7: =RANDBETWEEN(0,100) -> 91 | E7: =RANDBETWEEN(0,100) -> 33 | F7: =RANDBETWEEN(0,100) -> 87 | G7: =RANDBETWEEN(0,100) -> 4 | H7: =RANDBETWEEN(0,100) -> 55 | I7: =RANDBETWEEN(0,100) -> 0 | J7: =RANDBETWEEN(0,100) -> 85 | ... BM7: =RANDBETWEEN(0,100) -> 87
B8: Producto 2 | C8: =RANDBETWEEN(0,100) -> 57 | D8: =RANDBETWEEN(0,100) -> 10 | E8: =RANDBETWEEN(0,100) -> 87 | F8: =RANDBETWEEN(0,100) -> 53 | G8: =RANDBETWEEN(0,100) -> 91 | H8: =RANDBETWEEN(0,100) -> 84 | I8: =RANDBETWEEN(0,100) -> 22 | J8: =RANDBETWEEN(0,100) -> 73 | ... BM8: =RANDBETWEEN(0,100) -> 11
B9: Producto 3 | C9: =RANDBETWEEN(0,100) -> 32 | D9: =RANDBETWEEN(0,100) -> 91 | E9: =RANDBETWEEN(0,100) -> 21 | F9: =RANDBETWEEN(0,100) -> 44 | G9: =RANDBETWEEN(0,100) -> 49 | H9: =RANDBETWEEN(0,100) -> 2 | I9: =RANDBETWEEN(0,100) -> 2 | J9: =RANDBETWEEN(0,100) -> 2 | ... BM9: =RANDBETWEEN(0,100) -> 38
B10: Producto 4 | C10: =RANDBETWEEN(0,100) -> 65 | D10: =RANDBETWEEN(0,100) -> 8 | E10: =RANDBETWEEN(0,100) -> 7 | F10: =RANDBETWEEN(0,100) -> 78 | G10: =RANDBETWEEN(0,100) -> 99 | H10: =RANDBETWEEN(0,100) -> 27 | I10: =RANDBETWEEN(0,100) -> 59 | J10: =RANDBETWEEN(0,100) -> 20 | ... BM10: =RANDBETWEEN(0,100) -> 35
B11: Producto 5 | C11: =RANDBETWEEN(0,100) -> 89 | D11: =RANDBETWEEN(0,100) -> 9 | E11: =RANDBETWEEN(0,100) -> 38 | F11: =RANDBETWEEN(0,100) -> 98 | G11: =RANDBETWEEN(0,100) -> 26 | H11: =RANDBETWEEN(0,100) -> 57 | I11: =RANDBETWEEN(0,100) -> 95 | J11: =RANDBETWEEN(0,100) -> 59 | ... BM11: =RANDBETWEEN(0,100) -> 67
B12: Producto 6 | C12: =RANDBETWEEN(0,100) -> 74 | D12: =RANDBETWEEN(0,100) -> 68 | E12: =RANDBETWEEN(0,100) -> 28 | F12: =RANDBETWEEN(0,100) -> 62 | G12: =RANDBETWEEN(0,100) -> 4 | H12: =RANDBETWEEN(0,100) -> 49 | I12: =RANDBETWEEN(0,100) -> 8 | J12: =RANDBETWEEN(0,100) -> 71 | ... BM12: =RANDBETWEEN(0,100) -> 49
B13: Producto 7 | C13: =RANDBETWEEN(0,100) -> 39 | D13: =RANDBETWEEN(0,100) -> 6 | E13: =RANDBETWEEN(0,100) -> 38 | F13: =RANDBETWEEN(0,100) -> 76 | G13: =RANDBETWEEN(0,100) -> 71 | H13: =RANDBETWEEN(0,100) -> 40 | I13: =RANDBETWEEN(0,100) -> 60 | J13: =RANDBETWEEN(0,100) -> 2 | ... BM13: =RANDBETWEEN(0,100) -> 18
B14: Producto 8 | C14: =RANDBETWEEN(0,100) -> 84 | D14: =RANDBETWEEN(0,100) -> 13 | E14: =RANDBETWEEN(0,100) -> 25 | F14: =RANDBETWEEN(0,100) -> 34 | G14: =RANDBETWEEN(0,100) -> 33 | H14: =RANDBETWEEN(0,100) -> 45 | I14: =RANDBETWEEN(0,100) -> 84 | J14: =RANDBETWEEN(0,100) -> 78 | ... BM14: =RANDBETWEEN(0,100) -> 29
B15: Producto 9 | C15: =RANDBETWEEN(0,100) -> 29 | D15: =RANDBETWEEN(0,100) -> 7 | E15: =RANDBETWEEN(0,100) -> 69 | F15: =RANDBETWEEN(0,100) -> 73 | G15: =RANDBETWEEN(0,100) -> 26 | H15: =RANDBETWEEN(0,100) -> 15 | I15: =RANDBETWEEN(0,100) -> 70 | J15: =RANDBETWEEN(0,100) -> 13 | ... BM15: =RANDBETWEEN(0,100) -> 91
B16: TIENDA | C16: =RANDBETWEEN(0,100) -> 93 | D16: =RANDBETWEEN(0,100) -> 50 | E16: =RANDBETWEEN(0,100) -> 79 | F16: =RANDBETWEEN(0,100) -> 91 | G16: =RANDBETWEEN(0,100) -> 48 | H16: =RANDBETWEEN(0,100) -> 95 | I16: =RANDBETWEEN(0,100) -> 25 | J16: =RANDBETWEEN(0,100) -> 40 | ... BM16: =RANDBETWEEN(0,100) -> 14
B18: ▌ BLOQUE B — SEGUIMIENTO MENSUAL
B19: MÉTRICA | C19: ENE | D19: FEB | E19: MAR | F19: ABR | G19: MAY | H19: JUN | I19: JUL | J19: AGO | K19: SEP | L19: OCT | M19: NOV | N19: DIC | O19: TOTAL AÑO | BP19: ENE | BQ19: FEB | BR19: MAR | BS19: ABR | BT19: MAY | BU19: JUN | BV19: JUL | BW19: AGO | BX19: SEP | BY19: OCT | BZ19: NOV | CA19: DIC | CB19: TOTAL AÑO
B20: KPI | C20: =RANDBETWEEN(-20000,0) -> -9276 | D20: =RANDBETWEEN(-20000,0) -> -6529 | E20: =RANDBETWEEN(-20000,0) -> -3353 | F20: =RANDBETWEEN(-20000,0) -> -8989 | G20: =RANDBETWEEN(-20000,0) -> -14200 | H20: =RANDBETWEEN(-20000,0) -> -2848 | I20: =RANDBETWEEN(-20000,0) -> -14186 | J20: =RANDBETWEEN(-20000,0) -> -673 | ... N20: =RANDBETWEEN(-20000,0) -> -10842 | O20: =SUM(C20:N20) -> -86929
B21: KPI | C21: =RANDBETWEEN(1500000,3000000) -> 1521974 | D21: =RANDBETWEEN(1500000,3000000) -> 2327523 | E21: =RANDBETWEEN(1500000,3000000) -> 2657711 | F21: =RANDBETWEEN(1500000,3000000) -> 2420917 | G21: =RANDBETWEEN(1500000,3000000) -> 1947768 | H21: =RANDBETWEEN(1500000,3000000) -> 2230661 | I21: =RANDBETWEEN(1500000,3000000) -> 2845906 | J21: =RANDBETWEEN(1500000,3000000) -> 2917434 | ... N21: =RANDBETWEEN(1500000,3000000) -> 1695776 | O21: =SUM(C21:N21) -> 27162586 | CB21: =SUM(BP21:CA21) -> 0
B22: KPI | C22: =RANDBETWEEN(-15000,0) -> -14769 | D22: =RANDBETWEEN(-15000,0) -> -4960 | E22: =RANDBETWEEN(-15000,0) -> -9157 | F22: =RANDBETWEEN(-15000,0) -> -14021 | G22: =RANDBETWEEN(-15000,0) -> -13002 | H22: =RANDBETWEEN(-15000,0) -> -289 | I22: =RANDBETWEEN(-15000,0) -> -1106 | J22: =RANDBETWEEN(-15000,0) -> -4925 | ... N22: =RANDBETWEEN(-15000,0) -> -14806 | O22: =SUM(C22:N22) -> -93084 | CB22: =SUM(BP22:CA22) -> 0
B23: KPI | C23: =RANDBETWEEN(-15000,0) -> -9344 | D23: =RANDBETWEEN(-15000,0) -> -1735 | E23: =RANDBETWEEN(-15000,0) -> -13180 | F23: =RANDBETWEEN(-15000,0) -> -4945 | G23: =RANDBETWEEN(-15000,0) -> -13952 | H23: =RANDBETWEEN(-15000,0) -> -2000 | I23: =RANDBETWEEN(-15000,0) -> -5778 | J23: =RANDBETWEEN(-15000,0) -> -6062 | ... N23: =RANDBETWEEN(-15000,0) -> -5357 | O23: =SUM(C23:N23) -> -88322 | CB23: =SUM(BP23:CA23) -> 0
B24: KPI | C24: =RANDBETWEEN(-15000,0) -> -9035 | D24: =RANDBETWEEN(-15000,0) -> -10180 | E24: =RANDBETWEEN(-15000,0) -> -451 | F24: =RANDBETWEEN(-15000,0) -> -2697 | G24: =RANDBETWEEN(-15000,0) -> -2966 | H24: =RANDBETWEEN(-15000,0) -> -13075 | I24: =RANDBETWEEN(-15000,0) -> -3505 | J24: =RANDBETWEEN(-15000,0) -> -7761 | ... N24: =RANDBETWEEN(-15000,0) -> -6853 | O24: =SUM(C24:N24) -> -72255 | CB24: =SUM(BP24:CA24) -> 0
B25: KPI | O25: =SUM(C25:N25) -> 0 | CB25: =SUM(BP25:CA25) -> 0
B26: KPI | O26: =SUM(C26:N26) -> 0 | CB26: =SUM(BP26:CA26) -> 0
B27: KPI | C27: =RANDBETWEEN(0,10) -> 7 | D27: =RANDBETWEEN(0,10) -> 10 | E27: =RANDBETWEEN(0,10) -> 8 | F27: =RANDBETWEEN(0,10) -> 5 | G27: =RANDBETWEEN(0,10) -> 9 | H27: =RANDBETWEEN(0,10) -> 0 | I27: =RANDBETWEEN(0,10) -> 9 | J27: =RANDBETWEEN(0,10) -> 9 | ... N27: =RANDBETWEEN(0,10) -> 7 | O27: =SUM(C27:N27) -> 74
B28: KPI | C28: =RANDBETWEEN(0,1) -> 1 | D28: =RANDBETWEEN(0,1) -> 0 | E28: =RANDBETWEEN(0,1) -> 0 | F28: =RANDBETWEEN(0,1) -> 1 | G28: =RANDBETWEEN(0,1) -> 1 | H28: =RANDBETWEEN(0,1) -> 1 | I28: =RANDBETWEEN(0,1) -> 0 | J28: =RANDBETWEEN(0,1) -> 1 | ... N28: =RANDBETWEEN(0,1) -> 1 | O28: =AVERAGE(C28:N28) -> 0.66666667
B29: KPI | C29: =RAND() -> 0.36504105 | D29: =RAND() -> 0.15700536 | E29: =RAND() -> 0.30781982 | F29: =RAND() -> 0.74441887 | G29: =RAND() -> 0.063362462 | H29: =RAND() -> 0.021962266 | I29: =RAND() -> 0.57996121 | J29: =RAND() -> 0.3370886 | ... N29: =RAND() -> 0.44521886 | O29: =AVERAGE(C29:N29) -> 0.39076837
B30: KPI | C30: =RAND() -> 0.52693283 | D30: =RAND() -> 0.11547051 | E30: =RAND() -> 0.81343711 | F30: =RAND() -> 0.21030732 | G30: =RAND() -> 0.44900947 | H30: =RAND() -> 0.64159542 | I30: =RAND() -> 0.60330286 | J30: =RAND() -> 0.18912754 | ... N30: =RAND() -> 0.35965463 | O30: =AVERAGE(C30:N30) -> 0.41713062
B31: KPI | C31: =RAND() -> 0.85984471 | D31: =RAND() -> 0.29669966 | E31: =RAND() -> 0.36936317 | F31: =RAND() -> 0.23977274 | G31: =RAND() -> 0.60233042 | H31: =RAND() -> 0.71174058 | I31: =RAND() -> 0.77037261 | J31: =RAND() -> 0.34818028 | ... N31: =RAND() -> 0.61377351 | O31: =AVERAGE(C31:N31) -> 0.5449365
B32: KPI | C32: =RANDBETWEEN(0,100) -> 37 | D32: =RANDBETWEEN(0,100) -> 51 | E32: =RANDBETWEEN(0,100) -> 63 | F32: =RANDBETWEEN(0,100) -> 6 | G32: =RANDBETWEEN(0,100) -> 85 | H32: =RANDBETWEEN(0,100) -> 99 | I32: =RANDBETWEEN(0,100) -> 49 | J32: =RANDBETWEEN(0,100) -> 21 | ... N32: =RANDBETWEEN(0,100) -> 86 | O32: =AVERAGE(C32:N32) -> 60.916667
B33: ⚠️ INSTRUCCIONES:
B35: ▌ BLOQUE C — SEGUIMIENTO SEMANAL: ALERTAS
B36: SEMANA 1 | E36: SEMANA 2 | H36: SEMANA 3 | K36: SEMANA 4 | N36: SEMANA 5 | Q36: SEMANA 6 | T36: SEMANA 7 | W36: SEMANA 8 | BP36: ENE | BQ36: FEB | BR36: MAR | BS36: ABR | BT36: MAY | BU36: JUN | BV36: JUL | BW36: AGO | BX36: SEP | BY36: OCT | BZ36: NOV | CA36: DIC | CB36: TOTAL AÑO
B37: PRODUCTO | C37: KPI | D37: KPI | E37: PRODUCTO | F37: KPI | G37: KPI | H37: PRODUCTO | I37: KPI | J37: KPI | K37: PRODUCTO | L37: KPI | M37: KPI | N37: PRODUCTO | O37: KPI | P37: KPI | Q37: PRODUCTO | R37: KPI | S37: KPI | T37: PRODUCTO | U37: KPI | V37: KPI | W37: PRODUCTO | X37: KPI | Y37: KPI
B38: Producto 1 | C38: =RANDBETWEEN(-100, 0) -> -33 | E38: Producto 1 | F38: =RANDBETWEEN(-100, 0) -> -52 | H38: Producto 1 | I38: =RANDBETWEEN(-100, 0) -> -70 | K38: Producto 1 | L38: =RANDBETWEEN(-100, 0) -> -50 | N38: Producto 1 | O38: =RANDBETWEEN(-100, 0) -> -62 | Q38: Producto 1 | R38: =RANDBETWEEN(-100, 0) -> -7 | T38: Producto 1 | U38: =RANDBETWEEN(-100, 0) -> -19 | W38: Producto 1 | X38: =RANDBETWEEN(-100, 0) -> -45 | CB38: =SUM(BP38:CA38) -> 0
B39: Producto 2 | C39: =RANDBETWEEN(-100, 0) -> -12 | E39: Producto 2 | F39: =RANDBETWEEN(-100, 0) -> -40 | H39: Producto 2 | I39: =RANDBETWEEN(-100, 0) -> -74 | K39: Producto 2 | L39: =RANDBETWEEN(-100, 0) -> -56 | N39: Producto 2 | O39: =RANDBETWEEN(-100, 0) -> -32 | Q39: Producto 2 | R39: =RANDBETWEEN(-100, 0) -> -50 | T39: Producto 2 | U39: =RANDBETWEEN(-100, 0) -> -96 | W39: Producto 2 | X39: =RANDBETWEEN(-100, 0) -> 0 | CB39: =SUM(BP39:CA39) -> 0
B40: Producto 3 | C40: =RANDBETWEEN(-100, 0) -> -95 | E40: Producto 3 | F40: =RANDBETWEEN(-100, 0) -> -84 | H40: Producto 3 | I40: =RANDBETWEEN(-100, 0) -> -45 | K40: Producto 3 | L40: =RANDBETWEEN(-100, 0) -> -100 | N40: Producto 3 | O40: =RANDBETWEEN(-100, 0) -> -80 | Q40: Producto 3 | R40: =RANDBETWEEN(-100, 0) -> -99 | T40: Producto 3 | U40: =RANDBETWEEN(-100, 0) -> -1 | W40: Producto 3 | X40: =RANDBETWEEN(-100, 0) -> -61 | CB40: =SUM(BP40:CA40) -> 0
B41: Producto 4 | C41: =RANDBETWEEN(-100, 0) -> -84 | E41: Producto 4 | F41: =RANDBETWEEN(-100, 0) -> -88 | H41: Producto 4 | I41: =RANDBETWEEN(-100, 0) -> -34 | K41: Producto 4 | L41: =RANDBETWEEN(-100, 0) -> -10 | N41: Producto 4 | O41: =RANDBETWEEN(-100, 0) -> -85 | Q41: Producto 4 | R41: =RANDBETWEEN(-100, 0) -> -4 | T41: Producto 4 | U41: =RANDBETWEEN(-100, 0) -> -27 | W41: Producto 4 | X41: =RANDBETWEEN(-100, 0) -> -93 | CB41: =SUM(BP41:CA41) -> 0
B42: Producto 5 | C42: =RANDBETWEEN(-100, 0) -> -48 | E42: Producto 5 | F42: =RANDBETWEEN(-100, 0) -> -86 | H42: Producto 5 | I42: =RANDBETWEEN(-100, 0) -> -21 | K42: Producto 5 | L42: =RANDBETWEEN(-100, 0) -> -86 | N42: Producto 5 | O42: =RANDBETWEEN(-100, 0) -> -88 | Q42: Producto 5 | R42: =RANDBETWEEN(-100, 0) -> -79 | T42: Producto 5 | U42: =RANDBETWEEN(-100, 0) -> -10 | W42: Producto 5 | X42: =RANDBETWEEN(-100, 0) -> -57 | CB42: =SUM(BP42:CA42) -> 0
B43: Producto 6 | C43: =RANDBETWEEN(-100, 0) -> -29 | E43: Producto 6 | F43: =RANDBETWEEN(-100, 0) -> -37 | H43: Producto 6 | I43: =RANDBETWEEN(-100, 0) -> -3 | K43: Producto 6 | L43: =RANDBETWEEN(-100, 0) -> -72 | N43: Producto 6 | O43: =RANDBETWEEN(-100, 0) -> -68 | Q43: Producto 6 | R43: =RANDBETWEEN(-100, 0) -> -57 | T43: Producto 6 | U43: =RANDBETWEEN(-100, 0) -> -30 | W43: Producto 6 | X43: =RANDBETWEEN(-100, 0) -> -42

Sheet VISUAL SEG. SEMANAL EJEMPLO 1
B2: 📊 SEGUIMIENTO SEMANAL — 2026
B4: SEMANA 1 | G4: SEMANA 2 | L4: SEMANA 3
B5: Productos | C5: KPI | D5: KPI | E5: KPI | G5: Productos | H5: KPI | I5: KPI | J5: KPI | L5: Productos | M5: KPI | N5: KPI | O5: KPI
B6: Producto 1 | C6: ='DATOS CRUDOS EJEMPLO'!C7 -> 93 | D6: ='DATOS CRUDOS EJEMPLO'!D7 -> 91 | E6: ='DATOS CRUDOS EJEMPLO'!E7 -> 33 | G6: Producto 1 | H6: ='DATOS CRUDOS EJEMPLO'!F7 -> 87 | I6: ='DATOS CRUDOS EJEMPLO'!G7 -> 4 | J6: ='DATOS CRUDOS EJEMPLO'!H7 -> 55 | L6: Producto 1 | M6: ='DATOS CRUDOS EJEMPLO'!I7 -> 0 | N6: ='DATOS CRUDOS EJEMPLO'!J7 -> 85 | O6: ='DATOS CRUDOS EJEMPLO'!K7 -> 62
B7: Producto 2 | C7: ='DATOS CRUDOS EJEMPLO'!C8 -> 57 | D7: ='DATOS CRUDOS EJEMPLO'!D8 -> 10 | E7: ='DATOS CRUDOS EJEMPLO'!E8 -> 87 | G7: Producto 2 | H7: ='DATOS CRUDOS EJEMPLO'!F8 -> 53 | I7: ='DATOS CRUDOS EJEMPLO'!G8 -> 91 | J7: ='DATOS CRUDOS EJEMPLO'!H8 -> 84 | L7: Producto 2 | M7: ='DATOS CRUDOS EJEMPLO'!I8 -> 22 | N7: ='DATOS CRUDOS EJEMPLO'!J8 -> 73 | O7: ='DATOS CRUDOS EJEMPLO'!K8 -> 59
B8: Producto 3 | C8: ='DATOS CRUDOS EJEMPLO'!C9 -> 32 | D8: ='DATOS CRUDOS EJEMPLO'!D9 -> 91 | E8: ='DATOS CRUDOS EJEMPLO'!E9 -> 21 | G8: Producto 3 | H8: ='DATOS CRUDOS EJEMPLO'!F9 -> 44 | I8: ='DATOS CRUDOS EJEMPLO'!G9 -> 49 | J8: ='DATOS CRUDOS EJEMPLO'!H9 -> 2 | L8: Producto 3 | M8: ='DATOS CRUDOS EJEMPLO'!I9 -> 2 | N8: ='DATOS CRUDOS EJEMPLO'!J9 -> 2 | O8: ='DATOS CRUDOS EJEMPLO'!K9 -> 84
B9: Producto 4 | C9: ='DATOS CRUDOS EJEMPLO'!C10 -> 65 | D9: ='DATOS CRUDOS EJEMPLO'!D10 -> 8 | E9: ='DATOS CRUDOS EJEMPLO'!E10 -> 7 | G9: Producto 4 | H9: ='DATOS CRUDOS EJEMPLO'!F10 -> 78 | I9: ='DATOS CRUDOS EJEMPLO'!G10 -> 99 | J9: ='DATOS CRUDOS EJEMPLO'!H10 -> 27 | L9: Producto 4 | M9: ='DATOS CRUDOS EJEMPLO'!I10 -> 59 | N9: ='DATOS CRUDOS EJEMPLO'!J10 -> 20 | O9: ='DATOS CRUDOS EJEMPLO'!K10 -> 35
B10: Producto 5 | C10: ='DATOS CRUDOS EJEMPLO'!C11 -> 89 | D10: ='DATOS CRUDOS EJEMPLO'!D11 -> 9 | E10: ='DATOS CRUDOS EJEMPLO'!E11 -> 38 | G10: Producto 5 | H10: ='DATOS CRUDOS EJEMPLO'!F11 -> 98 | I10: ='DATOS CRUDOS EJEMPLO'!G11 -> 26 | J10: ='DATOS CRUDOS EJEMPLO'!H11 -> 57 | L10: Producto 5 | M10: ='DATOS CRUDOS EJEMPLO'!I11 -> 95 | N10: ='DATOS CRUDOS EJEMPLO'!J11 -> 59 | O10: ='DATOS CRUDOS EJEMPLO'!K11 -> 58
B11: Producto 6 | C11: ='DATOS CRUDOS EJEMPLO'!C12 -> 74 | D11: ='DATOS CRUDOS EJEMPLO'!D12 -> 68 | E11: ='DATOS CRUDOS EJEMPLO'!E12 -> 28 | G11: Producto 6 | H11: ='DATOS CRUDOS EJEMPLO'!F12 -> 62 | I11: ='DATOS CRUDOS EJEMPLO'!G12 -> 4 | J11: ='DATOS CRUDOS EJEMPLO'!H12 -> 49 | L11: Producto 6 | M11: ='DATOS CRUDOS EJEMPLO'!I12 -> 8 | N11: ='DATOS CRUDOS EJEMPLO'!J12 -> 71 | O11: ='DATOS CRUDOS EJEMPLO'!K12 -> 17
B12: Producto 7 | C12: ='DATOS CRUDOS EJEMPLO'!C13 -> 39 | D12: ='DATOS CRUDOS EJEMPLO'!D13 -> 6 | E12: ='DATOS CRUDOS EJEMPLO'!E13 -> 38 | G12: Producto 7 | H12: ='DATOS CRUDOS EJEMPLO'!F13 -> 76 | I12: ='DATOS CRUDOS EJEMPLO'!G13 -> 71 | J12: ='DATOS CRUDOS EJEMPLO'!H13 -> 40 | L12: Producto 7 | M12: ='DATOS CRUDOS EJEMPLO'!I13 -> 60 | N12: ='DATOS CRUDOS EJEMPLO'!J13 -> 2 | O12: ='DATOS CRUDOS EJEMPLO'!K13 -> 71
B13: Producto 8 | C13: ='DATOS CRUDOS EJEMPLO'!C14 -> 84 | D13: ='DATOS CRUDOS EJEMPLO'!D14 -> 13 | E13: ='DATOS CRUDOS EJEMPLO'!E14 -> 25 | G13: Producto 8 | H13: ='DATOS CRUDOS EJEMPLO'!F14 -> 34 | I13: ='DATOS CRUDOS EJEMPLO'!G14 -> 33 | J13: ='DATOS CRUDOS EJEMPLO'!H14 -> 45 | L13: Producto 8 | M13: ='DATOS CRUDOS EJEMPLO'!I14 -> 84 | N13: ='DATOS CRUDOS EJEMPLO'!J14 -> 78 | O13: ='DATOS CRUDOS EJEMPLO'!K14 -> 33
B14: Producto 9 | C14: ='DATOS CRUDOS EJEMPLO'!C15 -> 29 | D14: ='DATOS CRUDOS EJEMPLO'!D15 -> 7 | E14: ='DATOS CRUDOS EJEMPLO'!E15 -> 69 | G14: Producto 9 | H14: ='DATOS CRUDOS EJEMPLO'!F15 -> 73 | I14: ='DATOS CRUDOS EJEMPLO'!G15 -> 26 | J14: ='DATOS CRUDOS EJEMPLO'!H15 -> 15 | L14: Producto 9 | M14: ='DATOS CRUDOS EJEMPLO'!I15 -> 70 | N14: ='DATOS CRUDOS EJEMPLO'!J15 -> 13 | O14: ='DATOS CRUDOS EJEMPLO'!K15 -> 58
B15: TOTAL | C15: ='DATOS CRUDOS EJEMPLO'!C16 -> 93 | D15: 0 | E15: ='DATOS CRUDOS EJEMPLO'!E16 -> 79 | G15: TOTAL | H15: ='DATOS CRUDOS EJEMPLO'!F16 -> 91 | I15: ='DATOS CRUDOS EJEMPLO'!G16 -> 48 | J15: ='DATOS CRUDOS EJEMPLO'!H16 -> 95 | L15: TOTAL | M15: ='DATOS CRUDOS EJEMPLO'!I16 -> 25 | N15: ='DATOS CRUDOS EJEMPLO'!J16 -> 40 | O15: ='DATOS CRUDOS EJEMPLO'!K16 -> 48
B19: Semana 1 | G19: Semana 2 | M19: Semana 1
B20: Producto 2 | C20: Sección A | D20: Región Sur | E20: Región Norte | G20: Región Norte | H20: Empresa B | I20: Producto 2 | J20: Empresa B | L20: Región Norte | M20: Empresa A | N20: Producto 1 | O20: Producto 2
B21: ='DATOS CRUDOS EJEMPLO'!B38 -> Producto 1 | C21: ='DATOS CRUDOS EJEMPLO'!C38 -> -33 | G21: ='DATOS CRUDOS EJEMPLO'!E38 -> Producto 1 | H21: ='DATOS CRUDOS EJEMPLO'!F38 -> -52 | L21: ='DATOS CRUDOS EJEMPLO'!H38 -> Producto 1 | M21: ='DATOS CRUDOS EJEMPLO'!I38 -> -70
B22: ='DATOS CRUDOS EJEMPLO'!B39 -> Producto 2 | C22: ='DATOS CRUDOS EJEMPLO'!C39 -> -12 | G22: ='DATOS CRUDOS EJEMPLO'!E39 -> Producto 2 | H22: ='DATOS CRUDOS EJEMPLO'!F39 -> -40 | L22: ='DATOS CRUDOS EJEMPLO'!H39 -> Producto 2 | M22: ='DATOS CRUDOS EJEMPLO'!I39 -> -74
B23: ='DATOS CRUDOS EJEMPLO'!B40 -> Producto 3 | C23: ='DATOS CRUDOS EJEMPLO'!C40 -> -95 | G23: ='DATOS CRUDOS EJEMPLO'!E40 -> Producto 3 | H23: ='DATOS CRUDOS EJEMPLO'!F40 -> -84 | L23: ='DATOS CRUDOS EJEMPLO'!H40 -> Producto 3 | M23: ='DATOS CRUDOS EJEMPLO'!I40 -> -45
B24: ='DATOS CRUDOS EJEMPLO'!B41 -> Producto 4 | C24: ='DATOS CRUDOS EJEMPLO'!C41 -> -84 | G24: ='DATOS CRUDOS EJEMPLO'!E41 -> Producto 4 | H24: ='DATOS CRUDOS EJEMPLO'!F41 -> -88 | L24: ='DATOS CRUDOS EJEMPLO'!H41 -> Producto 4 | M24: ='DATOS CRUDOS EJEMPLO'!I41 -> -34
B25: ='DATOS CRUDOS EJEMPLO'!B42 -> Producto 5 | C25: ='DATOS CRUDOS EJEMPLO'!C42 -> -48 | G25: ='DATOS CRUDOS EJEMPLO'!E42 -> Producto 5 | H25: ='DATOS CRUDOS EJEMPLO'!F42 -> -86 | L25: ='DATOS CRUDOS EJEMPLO'!H42 -> Producto 5 | M25: ='DATOS CRUDOS EJEMPLO'!I42 -> -21
B26: ='DATOS CRUDOS EJEMPLO'!B43 -> Producto 6 | C26: ='DATOS CRUDOS EJEMPLO'!C43 -> -29 | G26: ='DATOS CRUDOS EJEMPLO'!E43 -> Producto 6 | H26: ='DATOS CRUDOS EJEMPLO'!F43 -> -37 | L26: ='DATOS CRUDOS EJEMPLO'!H43 -> Producto 6 | M26: ='DATOS CRUDOS EJEMPLO'!I43 -> -3

Sheet VISUAL SEG MENSUAL EJEMPLO 1
B2: 📦 DEMARCA — SEGUIMIENTO MENSUAL | M2: REFERENCIAS KPI
B4: GAP DEMARCA | G4: KPIs | N4: PILOTAJE ANUAL TOTAL
B5: MES | C5: GAP (€) | D5: PILOTAJE (€) | E5: ESTADO | G5: MES | H5: KPI | I5: VALOR | J5: ESTADO
B7: ENERO | C7: ='DATOS CRUDOS EJEMPLO'!C24 -> -9035 | D7: ='DATOS CRUDOS EJEMPLO'!C22 -> -14769 | E7: =IF(C7="","⏳ PENDIENTE", IF(C7<0, "🔴 NEGATIVO","✅ POSITIVO")) -> 🔴 NEGATIVO | G7: ENERO | H7: KPI | I7: ='DATOS CRUDOS EJEMPLO'!C27 -> 7 | J7: =IF(I7="","⏳ PENDIENTE", IF(I7>9,"✅ OK","🔴 Obj: >9")) -> 🔴 Obj: >9 | M7: Grafico
B8: FEBRERO | C8: ='DATOS CRUDOS EJEMPLO'!D24 -> -10180 | D8: ='DATOS CRUDOS EJEMPLO'!D22 -> -4960 | E8: =IF(C8="","⏳ PENDIENTE", IF(C8<0, "🔴 NEGATIVO","✅ POSITIVO")) -> 🔴 NEGATIVO | H8: KPI | I8: ='DATOS CRUDOS EJEMPLO'!C28 -> 1 | J8: =IF(I8="","⏳ PENDIENTE", IF(I8>95,"✅ OK","🔴 Obj: >95")) -> 🔴 Obj: >95
B9: MARZO | C9: ='DATOS CRUDOS EJEMPLO'!E24 -> -451 | D9: ='DATOS CRUDOS EJEMPLO'!E22 -> -9157 | E9: =IF(C9="","⏳ PENDIENTE", IF(C9<0, "🔴 NEGATIVO","✅ POSITIVO")) -> 🔴 NEGATIVO | H9: KPI | I9: ='DATOS CRUDOS EJEMPLO'!C29 -> 0.36504105 | J9: =IF(I9="","⏳ PENDIENTE", IF(I9<2,"✅ OK","🔴 Obj: <2")) -> ✅ OK
B10: ABRIL | C10: ='DATOS CRUDOS EJEMPLO'!F24 -> -2697 | D10: ='DATOS CRUDOS EJEMPLO'!F22 -> -14021 | E10: =IF(C10="","⏳ PENDIENTE", IF(C10<0, "🔴 NEGATIVO","✅ POSITIVO")) -> 🔴 NEGATIVO | H10: KPI | I10: ='DATOS CRUDOS EJEMPLO'!C30 -> 0.52693283 | J10: ℹ️ Sin objetivo
B11: MAYO | C11: ='DATOS CRUDOS EJEMPLO'!G24 -> -2966 | D11: ='DATOS CRUDOS EJEMPLO'!G22 -> -13002 | E11: =IF(C11="","⏳ PENDIENTE", IF(C11<0, "🔴 NEGATIVO","✅ POSITIVO")) -> 🔴 NEGATIVO | H11: KPI | I11: ='DATOS CRUDOS EJEMPLO'!C31 -> 0.85984471 | J11: =IF(I11="","⏳ PENDIENTE", IF(I11>2000,"✅ OK","🔴 Obj: 2000")) -> 🔴 Obj: 2000
B12: JUNIO | C12: ='DATOS CRUDOS EJEMPLO'!H24 -> -13075 | D12: ='DATOS CRUDOS EJEMPLO'!H22 -> -289 | E12: =IF(C12="","⏳ PENDIENTE", IF(C12<0, "🔴 NEGATIVO","✅ POSITIVO")) -> 🔴 NEGATIVO | G12: FEBRERO | H12: KPI | I12: ='DATOS CRUDOS EJEMPLO'!D27 -> 10 | J12: =IF(I12="","⏳ PENDIENTE", IF(I12>9,"✅ OK","🔴 Obj: >9")) -> ✅ OK
B13: JULIO | C13: ='DATOS CRUDOS EJEMPLO'!I24 -> -3505 | D13: ='DATOS CRUDOS EJEMPLO'!I22 -> -1106 | E13: =IF(C13="","⏳ PENDIENTE", IF(C13<0, "🔴 NEGATIVO","✅ POSITIVO")) -> 🔴 NEGATIVO | H13: KPI | I13: ='DATOS CRUDOS EJEMPLO'!D28 -> 0 | J13: =IF(I13="","⏳ PENDIENTE", IF(I13>95,"✅ OK","🔴 Obj: >95")) -> 🔴 Obj: >95
B14: AGOSTO | C14: ='DATOS CRUDOS EJEMPLO'!J24 -> -7761 | D14: ='DATOS CRUDOS EJEMPLO'!J22 -> -4925 | E14: =IF(C14="","⏳ PENDIENTE", IF(C14<0, "🔴 NEGATIVO","✅ POSITIVO")) -> 🔴 NEGATIVO | H14: KPI | I14: ='DATOS CRUDOS EJEMPLO'!D29 -> 0.15700536 | J14: =IF(I14="","⏳ PENDIENTE", IF(I14<2,"✅ OK","🔴 Obj: <2")) -> ✅ OK
B15: SEPTIEMBRE | C15: ='DATOS CRUDOS EJEMPLO'!K24 -> -2173 | D15: ='DATOS CRUDOS EJEMPLO'!K22 -> -10410 | E15: =IF(C15="","⏳ PENDIENTE", IF(C15<0, "🔴 NEGATIVO","✅ POSITIVO")) -> 🔴 NEGATIVO | H15: KPI | I15: ='DATOS CRUDOS EJEMPLO'!D30 -> 0.11547051 | J15: ℹ️ Sin objetivo
B16: OCTUBRE | C16: ='DATOS CRUDOS EJEMPLO'!L24 -> -10234 | D16: ='DATOS CRUDOS EJEMPLO'!L22 -> -1439 | E16: =IF(C16="","⏳ PENDIENTE", IF(C16<0, "🔴 NEGATIVO","✅ POSITIVO")) -> 🔴 NEGATIVO | H16: KPI | I16: ='DATOS CRUDOS EJEMPLO'!D31 -> 0.29669966 | J16: =IF(I16="","⏳ PENDIENTE", IF(I16>2000,"✅ OK","🔴 Obj: 2000")) -> 🔴 Obj: 2000
B17: NOVIEMBRE | C17: ='DATOS CRUDOS EJEMPLO'!M24 -> -3325 | D17: ='DATOS CRUDOS EJEMPLO'!M22 -> -4200 | E17: =IF(C17="","⏳ PENDIENTE", IF(C17<0, "🔴 NEGATIVO","✅ POSITIVO")) -> 🔴 NEGATIVO | G17: MARZO | H17: KPI | I17: ='DATOS CRUDOS EJEMPLO'!E27 -> 8 | J17: =IF(I17="","⏳ PENDIENTE", IF(I17>9,"✅ OK","🔴 Obj: >9")) -> 🔴 Obj: >9
B18: DICIEMBRE | C18: ='DATOS CRUDOS EJEMPLO'!N24 -> -6853 | D18: ='DATOS CRUDOS EJEMPLO'!N22 -> -14806 | E18: =IF(C18="","⏳ PENDIENTE", IF(C18<0, "🔴 NEGATIVO","✅ POSITIVO")) -> 🔴 NEGATIVO | H18: KPI | I18: ='DATOS CRUDOS EJEMPLO'!E28 -> 0 | J18: =IF(I18="","⏳ PENDIENTE", IF(I18>95,"✅ OK","🔴 Obj: >95")) -> 🔴 Obj: >95
B19: Producto 2 | D19: ='OT: SEG. Mensual'!N5 -> #REF! | H19: KPI | I19: ='DATOS CRUDOS EJEMPLO'!E29 -> 0.30781982 | J19: =IF(I19="","⏳ PENDIENTE", IF(I19<2,"✅ OK","🔴 Obj: <2")) -> ✅ OK
H20: KPI | I20: ='DATOS CRUDOS EJEMPLO'!E30 -> 0.81343711 | J20: ℹ️ Sin objetivo
H21: KPI | I21: ='DATOS CRUDOS EJEMPLO'!E31 -> 0.36936317 | J21: =IF(I21="","⏳ PENDIENTE", IF(I21>2000,"✅ OK","🔴 Obj: 2000")) -> 🔴 Obj: 2000
G22: ABRIL | H22: KPI | I22: ='DATOS CRUDOS EJEMPLO'!F27 -> 5 | J22: =IF(I22="","⏳ PENDIENTE", IF(I22>9,"✅ OK","🔴 Obj: >9")) -> 🔴 Obj: >9
H23: KPI | I23: ='DATOS CRUDOS EJEMPLO'!F28 -> 1 | J23: =IF(I23="","⏳ PENDIENTE", IF(I23>95,"✅ OK","🔴 Obj: >95")) -> 🔴 Obj: >95
H24: KPI | I24: ='DATOS CRUDOS EJEMPLO'!F29 -> 0.74441887 | J24: =IF(I24="","⏳ PENDIENTE", IF(I24<2,"✅ OK","🔴 Obj: <2")) -> ✅ OK
H25: KPI | I25: ='DATOS CRUDOS EJEMPLO'!F30 -> 0.21030732 | J25: ℹ️ Sin objetivo
H26: KPI | I26: ='DATOS CRUDOS EJEMPLO'!F31 -> 0.23977274 | J26: =IF(I26="","⏳ PENDIENTE", IF(I26>2000,"✅ OK","🔴 Obj: 2000")) -> 🔴 Obj: 2000
G27: MAYO | H27: KPI | I27: ='DATOS CRUDOS EJEMPLO'!G27 -> 9 | J27: =IF(I27="","⏳ PENDIENTE", IF(I27>9,"✅ OK","🔴 Obj: >9")) -> 🔴 Obj: >9
H28: KPI | I28: ='DATOS CRUDOS EJEMPLO'!G28 -> 1 | J28: =IF(I28="","⏳ PENDIENTE", IF(I28>95,"✅ OK","🔴 Obj: >95")) -> 🔴 Obj: >95
H29: KPI | I29: ='DATOS CRUDOS EJEMPLO'!G29 -> 0.063362462 | J29: =IF(I29="","⏳ PENDIENTE", IF(I29<2,"✅ OK","🔴 Obj: <2")) -> ✅ OK
H30: KPI | I30: ='DATOS CRUDOS EJEMPLO'!G30 -> 0.44900947 | J30: ℹ️ Sin objetivo
H31: KPI | I31: ='DATOS CRUDOS EJEMPLO'!G31 -> 0.60233042 | J31: =IF(I31="","⏳ PENDIENTE", IF(I31>2000,"✅ OK","🔴 Obj: 2000")) -> 🔴 Obj: 2000
G32: JUNIO | H32: KPI | I32: ='DATOS CRUDOS EJEMPLO'!H27 -> 0 | J32: =IF(I32="","⏳ PENDIENTE", IF(I32>9,"✅ OK","🔴 Obj: >9")) -> 🔴 Obj: >9
H33: KPI | I33: ='DATOS CRUDOS EJEMPLO'!H28 -> 1 | J33: =IF(I33="","⏳ PENDIENTE", IF(I33>95,"✅ OK","🔴 Obj: >95")) -> 🔴 Obj: >95
H34: KPI | I34: ='DATOS CRUDOS EJEMPLO'!H29 -> 0.021962266 | J34: =IF(I34="","⏳ PENDIENTE", IF(I34<2,"✅ OK","🔴 Obj: <2")) -> ✅ OK
H35: KPI | I35: ='DATOS CRUDOS EJEMPLO'!H30 -> 0.64159542 | J35: ℹ️ Sin objetivo
H36: KPI | I36: ='DATOS CRUDOS EJEMPLO'!H31 -> 0.71174058 | J36: =IF(I36="","⏳ PENDIENTE", IF(I36>2000,"✅ OK","🔴 Obj: 2000")) -> 🔴 Obj: 2000
G37: JULIO | H37: KPI | I37: ='DATOS CRUDOS EJEMPLO'!I27 -> 9 | J37: =IF(I37="","⏳ PENDIENTE", IF(I37>9,"✅ OK","🔴 Obj: >9")) -> 🔴 Obj: >9
H38: KPI | I38: ='DATOS CRUDOS EJEMPLO'!I28 -> 0 | J38: =IF(I38="","⏳ PENDIENTE", IF(I38>95,"✅ OK","🔴 Obj: >95")) -> 🔴 Obj: >95
H39: KPI | I39: ='DATOS CRUDOS EJEMPLO'!I29 -> 0.57996121 | J39: =IF(I39="","⏳ PENDIENTE", IF(I39<2,"✅ OK","🔴 Obj: <2")) -> ✅ OK
H40: KPI | I40: ='DATOS CRUDOS EJEMPLO'!I30 -> 0.60330286 | J40: ℹ️ Sin objetivo
H41: KPI | I41: ='DATOS CRUDOS EJEMPLO'!I31 -> 0.77037261 | J41: =IF(I41="","⏳ PENDIENTE", IF(I41>2000,"✅ OK","🔴 Obj: 2000")) -> 🔴 Obj: 2000
G42: AGOSTO | H42: KPI | I42: ='DATOS CRUDOS EJEMPLO'!J27 -> 9 | J42: =IF(I42="","⏳ PENDIENTE", IF(I42>9,"✅ OK","🔴 Obj: >9")) -> 🔴 Obj: >9
H43: KPI | I43: ='DATOS CRUDOS EJEMPLO'!J28 -> 1 | J43: =IF(I43="","⏳ PENDIENTE", IF(I43>95,"✅ OK","🔴 Obj: >95")) -> 🔴 Obj: >95
...

Sheet VISUAL SEMANAL SECCION
B2: 🚨 PRODUCTOS EN ALERTA — SECCIÓN X
B4: 🔴 Demarca negativa = pérdida 🟢 Demarca positiva ✍️ Rellena tu plan de acción | E4: 📋 Los datos se actualizan automáticamente
B6: ENERO
B7: SEMANA 1
B8: FAMILIA | C8: KPI | D8: PRODUCTO | G8: ✍️ PLAN DE ACCIÓN
B9: ='DATOS SECCION'!D7 -> FAM A | C9: ='DATOS SECCION'!E7 -> -2655 | D9: ='DATOS SECCION'!F7 -> -7182 | G9: Región Norte
D10: ='DATOS SECCION'!G7 -> -830 | G10: Región Sur
D11: ='DATOS SECCION'!H7 -> -3165
B12: ='DATOS SECCION'!D8 -> FAM B | C12: ='DATOS SECCION'!E8 -> -7461 | D12: ='DATOS SECCION'!F8 -> -4077 | G12: Empresa B
B15: ='DATOS SECCION'!D9 -> FAM C | C15: ='DATOS SECCION'!E9 -> -356
B18: Región Sur
B19: Sección B | C19: Sección A | D19: Sección A | G19: Empresa A
B20: Región Sur | C20: Sección B | D20: Empresa A | G20: Producto 2
D21: Empresa A
D22: Empresa A
B23: Producto 2
B26: Sección B
B29: Sección A
B30: Región Norte | C30: Empresa B | D30: Región Norte | G30: Empresa B
B31: Empresa B | C31: Producto 2 | D31: Producto 2 | G31: Producto 1
D32: Empresa B
D33: Producto 1
B34: Región Sur
B37: Producto 1
B40: Empresa A
B41: Región Norte
B42: Empresa A | C42: Empresa A | D42: Producto 1 | G42: Empresa A
B43: Empresa A | C43: Producto 1 | D43: Empresa A | G43: Empresa B
D44: Región Sur
D45: Región Norte
B46: Sección A
B49: Empresa B
B52: Producto 1
B53: Empresa A | C53: Producto 2 | D53: Producto 2 | G53: Producto 2
B54: Región Sur | C54: Sección B | D54: Producto 1 | G54: Producto 1
D55: Región Norte
D56: Empresa B
B57: Región Sur
B60: Producto 2
B63: Producto 2
...

Sheet DATOS SECCION
C2: Sección A
C4: ▌ BLOQUE 1 — ALERTAS SEMANALES
C5: ENERO | J5: FEBRERO
C6: SEMANA | D6: FAMILIA | E6: KPI | F6: KPI | G6: KPI | H6: KPI | J6: SEMANA | K6: FAMILIA | L6: KPI | M6: KPI | N6: KPI | O6: KPI
C7: Semana 1 | D7: FAM A | E7: =RANDBETWEEN(-10000, 0) -> -2655 | F7: =RANDBETWEEN(-10000, 0) -> -7182 | G7: =RANDBETWEEN(-10000, 0) -> -830 | H7: =RANDBETWEEN(-10000, 0) -> -3165 | J7: Semana 6 | K7: FAM A | L7: =RANDBETWEEN(-10000, 0) -> -2582 | M7: =RANDBETWEEN(-10000, 0) -> -8108 | N7: =RANDBETWEEN(-10000, 0) -> -2419 | O7: =RANDBETWEEN(-10000, 0) -> -3108
D8: FAM B | E8: =RANDBETWEEN(-10000, 0) -> -7461 | F8: =RANDBETWEEN(-10000, 0) -> -4077 | G8: =RANDBETWEEN(-10000, 0) -> -381 | H8: =RANDBETWEEN(-10000, 0) -> -596 | K8: FAM B | L8: =RANDBETWEEN(-10000, 0) -> -1740 | M8: =RANDBETWEEN(-10000, 0) -> -1723 | N8: =RANDBETWEEN(-10000, 0) -> -6256 | O8: =RANDBETWEEN(-10000, 0) -> -9006
D9: FAM C | E9: =RANDBETWEEN(-10000, 0) -> -356 | F9: =RANDBETWEEN(-10000, 0) -> -7930 | G9: =RANDBETWEEN(-10000, 0) -> -8158 | H9: =RANDBETWEEN(-10000, 0) -> -3759 | K9: FAM C | L9: =RANDBETWEEN(-10000, 0) -> -1190 | M9: =RANDBETWEEN(-10000, 0) -> -1957 | N9: =RANDBETWEEN(-10000, 0) -> -3538 | O9: =RANDBETWEEN(-10000, 0) -> -1285
C11: Semana 2 | D11: FAM A | E11: =RANDBETWEEN(-10000, 0) -> -7433 | F11: =RANDBETWEEN(-10000, 0) -> -3310 | G11: =RANDBETWEEN(-10000, 0) -> -9954 | H11: =RANDBETWEEN(-10000, 0) -> -9886 | J11: Semana 7 | K11: FAM A | L11: =RANDBETWEEN(-10000, 0) -> -4756 | M11: =RANDBETWEEN(-10000, 0) -> -2909 | N11: =RANDBETWEEN(-10000, 0) -> -5989 | O11: =RANDBETWEEN(-10000, 0) -> -4691
D12: FAM B | E12: =RANDBETWEEN(-10000, 0) -> -7259 | F12: =RANDBETWEEN(-10000, 0) -> -2469 | G12: =RANDBETWEEN(-10000, 0) -> -6101 | H12: =RANDBETWEEN(-10000, 0) -> -7078 | K12: FAM B | L12: =RANDBETWEEN(-10000, 0) -> -9427 | M12: =RANDBETWEEN(-10000, 0) -> -5852 | N12: =RANDBETWEEN(-10000, 0) -> -6498 | O12: =RANDBETWEEN(-10000, 0) -> -1010
D13: FAM C | E13: =RANDBETWEEN(-10000, 0) -> -6555 | F13: =RANDBETWEEN(-10000, 0) -> -2090 | G13: =RANDBETWEEN(-10000, 0) -> -3951 | H13: =RANDBETWEEN(-10000, 0) -> -4229 | K13: FAM C | L13: =RANDBETWEEN(-10000, 0) -> -5123 | M13: =RANDBETWEEN(-10000, 0) -> -6491 | N13: =RANDBETWEEN(-10000, 0) -> -8121 | O13: =RANDBETWEEN(-10000, 0) -> -7516
C15: Semana 3 | D15: FAM A | E15: =RANDBETWEEN(-10000, 0) -> -5063 | F15: =RANDBETWEEN(-10000, 0) -> -6188 | G15: =RANDBETWEEN(-10000, 0) -> -2963 | H15: =RANDBETWEEN(-10000, 0) -> -9883 | J15: Semana 8 | K15: FAM A | L15: =RANDBETWEEN(-10000, 0) -> -9685 | M15: =RANDBETWEEN(-10000, 0) -> -5629 | N15: =RANDBETWEEN(-10000, 0) -> -7506 | O15: =RANDBETWEEN(-10000, 0) -> -6812
D16: FAM B | E16: =RANDBETWEEN(-10000, 0) -> -1709 | F16: =RANDBETWEEN(-10000, 0) -> -3023 | G16: =RANDBETWEEN(-10000, 0) -> -783 | H16: =RANDBETWEEN(-10000, 0) -> -5221 | K16: FAM B | L16: =RANDBETWEEN(-10000, 0) -> -8688 | M16: =RANDBETWEEN(-10000, 0) -> -6597 | N16: =RANDBETWEEN(-10000, 0) -> -7492 | O16: =RANDBETWEEN(-10000, 0) -> -7730
D17: FAM C | E17: =RANDBETWEEN(-10000, 0) -> -3765 | F17: =RANDBETWEEN(-10000, 0) -> -6395 | G17: =RANDBETWEEN(-10000, 0) -> -2391 | H17: =RANDBETWEEN(-10000, 0) -> -1539 | K17: FAM C | L17: =RANDBETWEEN(-10000, 0) -> -163 | M17: =RANDBETWEEN(-10000, 0) -> -9776 | N17: =RANDBETWEEN(-10000, 0) -> -7946 | O17: =RANDBETWEEN(-10000, 0) -> -7908
C19: Semana 4 | D19: FAM A | E19: =RANDBETWEEN(-10000, 0) -> -5969 | F19: =RANDBETWEEN(-10000, 0) -> -6430 | G19: =RANDBETWEEN(-10000, 0) -> -9035 | H19: =RANDBETWEEN(-10000, 0) -> -5793 | J19: Semana 9 | K19: FAM A | L19: =RANDBETWEEN(-10000, 0) -> -2941 | M19: =RANDBETWEEN(-10000, 0) -> -5150 | N19: =RANDBETWEEN(-10000, 0) -> -7555 | O19: =RANDBETWEEN(-10000, 0) -> -9326
D20: FAM B | E20: =RANDBETWEEN(-10000, 0) -> -3178 | F20: =RANDBETWEEN(-10000, 0) -> -3677 | G20: =RANDBETWEEN(-10000, 0) -> -5218 | H20: =RANDBETWEEN(-10000, 0) -> -59 | K20: FAM B | L20: =RANDBETWEEN(-10000, 0) -> -5638 | M20: =RANDBETWEEN(-10000, 0) -> -5167 | N20: =RANDBETWEEN(-10000, 0) -> -7769 | O20: =RANDBETWEEN(-10000, 0) -> -5162
D21: FAM C | E21: =RANDBETWEEN(-10000, 0) -> -4591 | F21: =RANDBETWEEN(-10000, 0) -> -953 | G21: =RANDBETWEEN(-10000, 0) -> -4861 | H21: =RANDBETWEEN(-10000, 0) -> -7931 | K21: FAM C | L21: =RANDBETWEEN(-10000, 0) -> -8816 | M21: =RANDBETWEEN(-10000, 0) -> -6303 | N21: =RANDBETWEEN(-10000, 0) -> -2625 | O21: =RANDBETWEEN(-10000, 0) -> -2000
C23: Semana 5 | D23: FAM A | E23: =RANDBETWEEN(-10000, 0) -> -166 | F23: =RANDBETWEEN(-10000, 0) -> -3970 | G23: =RANDBETWEEN(-10000, 0) -> -5979 | H23: =RANDBETWEEN(-10000, 0) -> -7039
D24: FAM B | E24: =RANDBETWEEN(-10000, 0) -> -7025 | F24: =RANDBETWEEN(-10000, 0) -> -3758 | G24: =RANDBETWEEN(-10000, 0) -> -8476 | H24: =RANDBETWEEN(-10000, 0) -> -1918
D25: FAM C | E25: =RANDBETWEEN(-10000, 0) -> -5713 | F25: =RANDBETWEEN(-10000, 0) -> -6342 | G25: =RANDBETWEEN(-10000, 0) -> -5732 | H25: =RANDBETWEEN(-10000, 0) -> -5172
C27: ▌ BLOQUE 2 — SEGUIMIENTO MENSUAL
C28: MÉTRICA | D28: ENE | E28: FEB | F28: MAR | G28: ABR | H28: MAY | I28: JUN | J28: JUL | K28: AGO | L28: SEP | M28: OCT | N28: NOV | O28: DIC | P28: TOTAL AÑO
B29: 2025 | C29: KPI | D29: =RANDBETWEEN(0,1000) -> 879 | E29: =RANDBETWEEN(0,1000) -> 409 | F29: =RANDBETWEEN(0,1000) -> 979 | G29: =RANDBETWEEN(0,1000) -> 603 | H29: =RANDBETWEEN(0,1000) -> 179 | I29: =RANDBETWEEN(0,1000) -> 596 | J29: =RANDBETWEEN(0,1000) -> 3 | K29: =RANDBETWEEN(0,1000) -> 594 | ... O29: =RANDBETWEEN(0,1000) -> 903 | P29: =SUM(D29:O29) -> 6702
C30: KPI | D30: =RANDBETWEEN(0,1000) -> 920 | E30: =RANDBETWEEN(0,1000) -> 177 | F30: =RANDBETWEEN(0,1000) -> 600 | G30: =RANDBETWEEN(0,1000) -> 482 | H30: =RANDBETWEEN(0,1000) -> 758 | I30: =RANDBETWEEN(0,1000) -> 649 | J30: =RANDBETWEEN(0,1000) -> 33 | K30: =RANDBETWEEN(0,1000) -> 825 | ... O30: =RANDBETWEEN(0,1000) -> 469 | P30: =SUM(D30:O30) -> 6450
C31: KPI | D31: =RANDBETWEEN(0,1000) -> 701 | E31: =RANDBETWEEN(0,1000) -> 373 | F31: =RANDBETWEEN(0,1000) -> 87 | G31: =RANDBETWEEN(0,1000) -> 600 | H31: =RANDBETWEEN(0,1000) -> 180 | I31: =RANDBETWEEN(0,1000) -> 7 | J31: =RANDBETWEEN(0,1000) -> 5 | K31: =RANDBETWEEN(0,1000) -> 755 | ... O31: =RANDBETWEEN(0,1000) -> 670 | P31: =AVERAGE(D31:O31) -> 401.33333
C32: KPI | D32: =RANDBETWEEN(0,1000) -> 359 | E32: =RANDBETWEEN(0,1000) -> 603 | F32: =RANDBETWEEN(0,1000) -> 271 | G32: =RANDBETWEEN(0,1000) -> 826 | H32: =RANDBETWEEN(0,1000) -> 813 | I32: =RANDBETWEEN(0,1000) -> 570 | J32: =RANDBETWEEN(0,1000) -> 460 | K32: =RANDBETWEEN(0,1000) -> 200 | ... O32: =RANDBETWEEN(0,1000) -> 975 | P32: =SUM(F32:O32) -> 6018
C33: KPI | D33: =RANDBETWEEN(0,1000) -> 867 | E33: =RANDBETWEEN(0,1000) -> 29 | F33: =RANDBETWEEN(0,1000) -> 970 | G33: =RANDBETWEEN(0,1000) -> 555 | H33: =RANDBETWEEN(0,1000) -> 307 | I33: =RANDBETWEEN(0,1000) -> 570 | J33: =RANDBETWEEN(0,1000) -> 858 | K33: =RANDBETWEEN(0,1000) -> 226 | ... O33: =RANDBETWEEN(0,1000) -> 687 | P33: =AVERAGE(D33:O33) -> 535.58333
C34: KPI | D34: =RANDBETWEEN(0,1000) -> 380 | E34: =RANDBETWEEN(0,1000) -> 922 | F34: =RANDBETWEEN(0,1000) -> 272 | G34: =RANDBETWEEN(0,1000) -> 447 | H34: =RANDBETWEEN(0,1000) -> 330 | I34: =RANDBETWEEN(0,1000) -> 691 | J34: =RANDBETWEEN(0,1000) -> 515 | K34: =RANDBETWEEN(0,1000) -> 437 | ... O34: =RANDBETWEEN(0,1000) -> 483 | P34: =AVERAGE(D34:O34) -> 512.33333
D35: =RANDBETWEEN(0,1000) -> 328 | E35: =RANDBETWEEN(0,1000) -> 328 | F35: =RANDBETWEEN(0,1000) -> 51 | G35: =RANDBETWEEN(0,1000) -> 834 | H35: =RANDBETWEEN(0,1000) -> 561 | I35: =RANDBETWEEN(0,1000) -> 765 | J35: =RANDBETWEEN(0,1000) -> 509 | K35: =RANDBETWEEN(0,1000) -> 174 | ... O35: =RANDBETWEEN(0,1000) -> 513
B36: 2026 | C36: KPI | D36: =RANDBETWEEN(0,1000) -> 592 | E36: =RANDBETWEEN(0,1000) -> 952 | F36: =RANDBETWEEN(0,1000) -> 922 | G36: =RANDBETWEEN(0,1000) -> 707 | H36: =RANDBETWEEN(0,1000) -> 22 | I36: =RANDBETWEEN(0,1000) -> 194 | J36: =RANDBETWEEN(0,1000) -> 393 | K36: =RANDBETWEEN(0,1000) -> 815 | ... O36: =RANDBETWEEN(0,1000) -> 989 | P36: =SUM(D36:O36) -> 6285
C37: KPI | D37: =RANDBETWEEN(0,1000) -> 898 | E37: =RANDBETWEEN(0,1000) -> 989 | F37: =RANDBETWEEN(0,1000) -> 160 | G37: =RANDBETWEEN(0,1000) -> 580 | H37: =RANDBETWEEN(0,1000) -> 15 | I37: =RANDBETWEEN(0,1000) -> 966 | J37: =RANDBETWEEN(0,1000) -> 15 | K37: =RANDBETWEEN(0,1000) -> 308 | ... O37: =RANDBETWEEN(0,1000) -> 187 | P37: =SUM(D37:O37) -> 6066
C38: KPI | D38: =RANDBETWEEN(0,1000) -> 30 | E38: =RANDBETWEEN(0,1000) -> 663 | F38: =RANDBETWEEN(0,1000) -> 353 | G38: =RANDBETWEEN(0,1000) -> 390 | H38: =RANDBETWEEN(0,1000) -> 578 | I38: =RANDBETWEEN(0,1000) -> 873 | J38: =RANDBETWEEN(0,1000) -> 817 | K38: =RANDBETWEEN(0,1000) -> 15 | ... O38: =RANDBETWEEN(0,1000) -> 631 | P38: =AVERAGE(D38:O38) -> 420.33333
C39: KPI | D39: =RANDBETWEEN(0,1000) -> 609 | E39: =RANDBETWEEN(0,1000) -> 786 | F39: =RANDBETWEEN(0,1000) -> 694 | G39: =RANDBETWEEN(0,1000) -> 772 | H39: =RANDBETWEEN(0,1000) -> 830 | I39: =RANDBETWEEN(0,1000) -> 78 | J39: =RANDBETWEEN(0,1000) -> 745 | K39: =RANDBETWEEN(0,1000) -> 95 | ... O39: =RANDBETWEEN(0,1000) -> 496 | P39: =AVERAGE(D39:O39) -> 583.33333
C40: KPI | D40: =RANDBETWEEN(0,1000) -> 197 | E40: =RANDBETWEEN(0,1000) -> 821 | F40: =RANDBETWEEN(0,1000) -> 803 | G40: =RANDBETWEEN(0,1000) -> 904 | H40: =RANDBETWEEN(0,1000) -> 46 | I40: =RANDBETWEEN(0,1000) -> 188 | J40: =RANDBETWEEN(0,1000) -> 962 | K40: =RANDBETWEEN(0,1000) -> 700 | ... O40: =RANDBETWEEN(0,1000) -> 637 | P40: =AVERAGE(D40:O40) -> 539
C41: KPI | D41: =RANDBETWEEN(0,1000) -> 917 | E41: =RANDBETWEEN(0,1000) -> 996 | F41: =RANDBETWEEN(0,1000) -> 622 | G41: =RANDBETWEEN(0,1000) -> 873 | H41: =RANDBETWEEN(0,1000) -> 580 | I41: =RANDBETWEEN(0,1000) -> 548 | J41: =RANDBETWEEN(0,1000) -> 577 | K41: =RANDBETWEEN(0,1000) -> 445 | ... O41: =RANDBETWEEN(0,1000) -> 867 | P41: =AVERAGE(D41:O41) -> 647.41667
C43: Sección B
